Workbook

Sheet RAT
B1: RAT - RELATÓRIO DE ATENDIMENTO
B2: EXECUÇÃO DOS SERVIÇOS
B3: Número da solicitação | D3: Data/hora Abertura | G3: Contrato de Manutenção | J3: Contratada
B4: 250195016 | D4: 46361 | G4: 2025.7421.0908 | J4: MAFFENG ENGENHARIA E MANUTENÇÃO
B5: Sinistro | D5: Prazo de atendimento | G5: Tipo de Manutenção | J5: Nível de Ocorrência
B6: (Sim/Não) | G6: (Preventiva/Corretiva) | J6: (Emergencial/Urgente/Normal)
B7: Não | D7: 46080 | G7: Preventiva | J7: Normal
B8: Prefixo / SB - Dependência Beneficiada | G8: Endereço
B9: 7027 | C9: =VLOOKUP(B9,Prefixos!A4:E112,3,0) -> VILA TATETUBA | G9: =VLOOKUP(B9,Prefixos!A4:E112,4,0) -> AV.PRES.JUSCELINO KUBITSCHEK 8260
B10: Informações de Contato | G10: Matrícula / Nome - Funcionário Solicitante
B11: Responsável | G11: F6798701 - SISTEMA
B12: SERVIÇOS SOLICITADOS - Portal de Manutenção
B13: Descrição do serviço, Tipo, Quantidade, Local de Atendimento e Prioridade* | K13: Situação (Código**)
B14: Levantamento Preventivo | K14: 4
B15: * Preencher com as informações do Portal de Manutenção da DISEC. ** Preencher o campo situação com os códigos a seguir: 1. Serviço concluído sem pendências; 2. Serviço cancelado pelo demandante; 3. Atendimento Parcial; 4. Confecção de orçamento, para execução do serviço demanda autorização por parte do CESUP Suprimentos; 5. Não Atendido. 6. Mitigação de Riscos ou primeiro atendimento
B16: ORÇAMENTO DOS SERVIÇOS REALIZADOS
B17: ITEM | C17: DESCRIÇÃO | I17: QTD. | J17: UND. | K17: VALOR UNITÁRIO | M17: MAT UNIT | N17: MAO. UNIT | O17: MAT TOTAL | P17: MAO TOTAL | Q17: VALOR TOTAL
B18: 1.2 | C18: =UPPER(VLOOKUP(B18,Valores!$A$7:$J$537,2,0)) -> DESLOCAMENTO | I18: 15 | J18: =UPPER(VLOOKUP(B18,Valores!$A$7:$J$537,4,0)) -> KM | K18: =UPPER(VLOOKUP(B18,Valores!$A$7:$J$537,7,0)) -> 2,15 | M18: =UPPER(VLOOKUP(B18,Valores!$A$7:$J$537,5,0)) -> 1,51 | N18: =UPPER(VLOOKUP(B18,Valores!$A$7:$J$537,6,0)) -> 0,64 | O18: =M18*I18 -> 22.65 | P18: =N18*I18 -> 9.6 | Q18: =K18*I18 -> 32.25
B19: 1.1 | C19: =UPPER(VLOOKUP(B19,Valores!$A$7:$J$537,2,0)) -> CHAMADO | I19: 1 | J19: =UPPER(VLOOKUP(B19,Valores!$A$7:$J$537,4,0)) -> UN | K19: =UPPER(VLOOKUP(B19,Valores!$A$7:$J$537,7,0)) -> 76,34 | M19: =UPPER(VLOOKUP(B19,Valores!$A$7:$J$537,5,0)) -> 0 | N19: =UPPER(VLOOKUP(B19,Valores!$A$7:$J$537,6,0)) -> 76,34 | O19: =M19*I19 -> 0 | P19: =N19*I19 -> 76.34 | Q19: =K19*I19 -> 76.34
C20: =UPPER(VLOOKUP(B20,Valores!$A$7:$J$537,2,0)) -> #N/A | J20: =UPPER(VLOOKUP(B20,Valores!$A$7:$J$537,4,0)) -> #N/A | K20: =UPPER(VLOOKUP(B20,Valores!$A$7:$J$537,7,0)) -> #N/A | M20: =UPPER(VLOOKUP(B20,Valores!$A$7:$J$537,5,0)) -> #N/A | N20: =UPPER(VLOOKUP(B20,Valores!$A$7:$J$537,6,0)) -> #N/A | O20: =M20*I20 -> #N/A | P20: =N20*I20 -> #N/A | Q20: =K20*I20 -> #N/A
C21: =UPPER(VLOOKUP(B21,Valores!$A$7:$J$537,2,0)) -> #N/A | J21: =UPPER(VLOOKUP(B21,Valores!$A$7:$J$537,4,0)) -> #N/A | K21: =UPPER(VLOOKUP(B21,Valores!$A$7:$J$537,7,0)) -> #N/A | M21: =UPPER(VLOOKUP(B21,Valores!$A$7:$J$537,5,0)) -> #N/A | N21: =UPPER(VLOOKUP(B21,Valores!$A$7:$J$537,6,0)) -> #N/A | O21: =M21*I21 -> #N/A | P21: =N21*I21 -> #N/A | Q21: =K21*I21 -> #N/A
C22: =UPPER(VLOOKUP(B22,Valores!$A$7:$J$537,2,0)) -> #N/A | J22: =UPPER(VLOOKUP(B22,Valores!$A$7:$J$537,4,0)) -> #N/A | K22: =UPPER(VLOOKUP(B22,Valores!$A$7:$J$537,7,0)) -> #N/A | M22: =UPPER(VLOOKUP(B22,Valores!$A$7:$J$537,5,0)) -> #N/A | N22: =UPPER(VLOOKUP(B22,Valores!$A$7:$J$537,6,0)) -> #N/A | O22: =M22*I22 -> #N/A | P22: =N22*I22 -> #N/A | Q22: =K22*I22 -> #N/A
C23: =UPPER(VLOOKUP(B23,Valores!$A$7:$J$537,2,0)) -> #N/A | J23: =UPPER(VLOOKUP(B23,Valores!$A$7:$J$537,4,0)) -> #N/A | K23: =UPPER(VLOOKUP(B23,Valores!$A$7:$J$537,7,0)) -> #N/A | M23: =UPPER(VLOOKUP(B23,Valores!$A$7:$J$537,5,0)) -> #N/A | N23: =UPPER(VLOOKUP(B23,Valores!$A$7:$J$537,6,0)) -> #N/A | O23: =M23*I23 -> #N/A | P23: =N23*I23 -> #N/A | Q23: =K23*I23 -> #N/A
C24: =UPPER(VLOOKUP(B24,Valores!$A$7:$J$537,2,0)) -> #N/A | J24: =UPPER(VLOOKUP(B24,Valores!$A$7:$J$537,4,0)) -> #N/A | K24: =UPPER(VLOOKUP(B24,Valores!$A$7:$J$537,7,0)) -> #N/A | M24: =UPPER(VLOOKUP(B24,Valores!$A$7:$J$537,5,0)) -> #N/A | N24: =UPPER(VLOOKUP(B24,Valores!$A$7:$J$537,6,0)) -> #N/A | O24: =M24*I24 -> #N/A | P24: =N24*I24 -> #N/A | Q24: =K24*I24 -> #N/A
C25: =UPPER(VLOOKUP(B25,Valores!$A$7:$J$537,2,0)) -> #N/A | J25: =UPPER(VLOOKUP(B25,Valores!$A$7:$J$537,4,0)) -> #N/A | K25: =UPPER(VLOOKUP(B25,Valores!$A$7:$J$537,7,0)) -> #N/A | M25: =UPPER(VLOOKUP(B25,Valores!$A$7:$J$537,5,0)) -> #N/A | N25: =UPPER(VLOOKUP(B25,Valores!$A$7:$J$537,6,0)) -> #N/A | O25: =M25*I25 -> #N/A | P25: =N25*I25 -> #N/A | Q25: =K25*I25 -> #N/A
C26: =UPPER(VLOOKUP(B26,Valores!$A$7:$J$537,2,0)) -> #N/A | J26: =UPPER(VLOOKUP(B26,Valores!$A$7:$J$537,4,0)) -> #N/A | K26: =UPPER(VLOOKUP(B26,Valores!$A$7:$J$537,7,0)) -> #N/A | M26: =UPPER(VLOOKUP(B26,Valores!$A$7:$J$537,5,0)) -> #N/A | N26: =UPPER(VLOOKUP(B26,Valores!$A$7:$J$537,6,0)) -> #N/A | O26: =M26*I26 -> #N/A | P26: =N26*I26 -> #N/A | Q26: =K26*I26 -> #N/A
C27: =UPPER(VLOOKUP(B27,Valores!$A$7:$J$537,2,0)) -> #N/A | J27: =UPPER(VLOOKUP(B27,Valores!$A$7:$J$537,4,0)) -> #N/A | K27: =UPPER(VLOOKUP(B27,Valores!$A$7:$J$537,7,0)) -> #N/A | M27: =UPPER(VLOOKUP(B27,Valores!$A$7:$J$537,5,0)) -> #N/A | N27: =UPPER(VLOOKUP(B27,Valores!$A$7:$J$537,6,0)) -> #N/A | O27: =M27*I27 -> #N/A | P27: =N27*I27 -> #N/A | Q27: =K27*I27 -> #N/A
C28: =UPPER(VLOOKUP(B28,Valores!$A$7:$J$537,2,0)) -> #N/A | J28: =UPPER(VLOOKUP(B28,Valores!$A$7:$J$537,4,0)) -> #N/A | K28: =UPPER(VLOOKUP(B28,Valores!$A$7:$J$537,7,0)) -> #N/A | M28: =UPPER(VLOOKUP(B28,Valores!$A$7:$J$537,5,0)) -> #N/A | N28: =UPPER(VLOOKUP(B28,Valores!$A$7:$J$537,6,0)) -> #N/A | O28: =M28*I28 -> #N/A | P28: =N28*I28 -> #N/A | Q28: =K28*I28 -> #N/A
C29: =UPPER(VLOOKUP(B29,Valores!$A$7:$J$537,2,0)) -> #N/A | J29: =UPPER(VLOOKUP(B29,Valores!$A$7:$J$537,4,0)) -> #N/A | K29: =UPPER(VLOOKUP(B29,Valores!$A$7:$J$537,7,0)) -> #N/A | M29: =UPPER(VLOOKUP(B29,Valores!$A$7:$J$537,5,0)) -> #N/A | N29: =UPPER(VLOOKUP(B29,Valores!$A$7:$J$537,6,0)) -> #N/A | O29: =M29*I29 -> #N/A | P29: =N29*I29 -> #N/A | Q29: =K29*I29 -> #N/A
C30: =UPPER(VLOOKUP(B30,Valores!$A$7:$J$537,2,0)) -> #N/A | J30: =UPPER(VLOOKUP(B30,Valores!$A$7:$J$537,4,0)) -> #N/A | K30: =UPPER(VLOOKUP(B30,Valores!$A$7:$J$537,7,0)) -> #N/A | M30: =UPPER(VLOOKUP(B30,Valores!$A$7:$J$537,5,0)) -> #N/A | N30: =UPPER(VLOOKUP(B30,Valores!$A$7:$J$537,6,0)) -> #N/A | O30: =M30*I30 -> #N/A | P30: =N30*I30 -> #N/A | Q30: =K30*I30 -> #N/A
C31: =UPPER(VLOOKUP(B31,Valores!$A$7:$J$537,2,0)) -> #N/A | J31: =UPPER(VLOOKUP(B31,Valores!$A$7:$J$537,4,0)) -> #N/A | K31: =UPPER(VLOOKUP(B31,Valores!$A$7:$J$537,7,0)) -> #N/A | M31: =UPPER(VLOOKUP(B31,Valores!$A$7:$J$537,5,0)) -> #N/A | N31: =UPPER(VLOOKUP(B31,Valores!$A$7:$J$537,6,0)) -> #N/A | O31: =M31*I31 -> #N/A | P31: =N31*I31 -> #N/A | Q31: =K31*I31 -> #N/A
... C50: =UPPER(VLOOKUP(B50,Valores!$A$7:$J$537,2,0)) -> #N/A | J50: =UPPER(VLOOKUP(B50,Valores!$A$7:$J$537,4,0)) -> #N/A | K50: =UPPER(VLOOKUP(B50,Valores!$A$7:$J$537,7,0)) -> #N/A | M50: =UPPER(VLOOKUP(B50,Valores!$A$7:$J$537,5,0)) -> #N/A | N50: =UPPER(VLOOKUP(B50,Valores!$A$7:$J$537,6,0)) -> #N/A | O50: =M50*I50 -> #N/A | P50: =N50*I50 -> #N/A | Q50: =K50*I50 -> #N/A
B51: RESUMO DO ORÇAMENTO DOS SERVIÇOS SOLICITADOS
B52: Data / Hora Conclusão | G52: Valor de Materiais + Mão de Obra | J52: Valor Total
B53: =F68 -> 46078 | G53: =SUM(O18:O50) -> #N/A | H53: + | I53: =SUM(P18:P50) -> #N/A | J53: =I53+G53 -> #N/A
B54: Observações
C58: ________________________________________________ | I58: ___________________________________________________________________________________
C62: VISTO REPRESENTANTE DA EMPRESA CONTRATADA | I62: CARIMBO E VISTO DA DEPENDÊNCIA
B64: TÉCNICO | J64: ENGENHEIRO
J65: ______________________________________
...

Sheet Conformidade
A1: RAT - RELATÓRIO DE ATENDIMENTO
A2: Conformidade do atendimento no local dos serviços
A3: Número da solicitação | C3: Data/hora Abertura | F3: Contrato de Manutenção | I3: Contratada
A4: =RAT!B4 -> 250195016 | C4: =RAT!D4 -> 46361 | F4: 2025.7421.0908 | I4: MAFFENG ENGENHARIA E MANUTENÇÃO
A5: Sinistro | C5: Prazo de atendimento | F5: Tipo de Manutenção | I5: Nível de Ocorrência
A6: (Sim/Não) | F6: (Preventiva/Corretiva) | I6: (Emergencial/Urgente/Normal)
A7: =RAT!B7 -> Não | C7: =RAT!D7 -> 46080 | F7: =RAT!G7 -> Preventiva | I7: =RAT!J7 -> Normal
A8: Prefixo / SB - Dependência Beneficiada | F8: Endereço
A9: =RAT!B9 -> 7027 | B9: =RAT!C9 -> VILA TATETUBA | F9: =RAT!G9 -> AV.PRES.JUSCELINO KUBITSCHEK 8260
A10: Informações de Contato | F10: Matrícula / Nome - Funcionário Solicitante
A11: =RAT!B11 -> Responsável | F11: =RAT!G11 -> F6798701 - SISTEMA
A12: MÓDULO DEMANDANTE / BENEFICIÁRIO / CONTRATANTE PREENCHIMENTO PELO PREPOSTO DO BANCO DO BRASIL
A13: Matrícula | C13: Nome Funcionário Preposto
A15: Questionário | I15: Atendeu | K15: Não Atendeu
A16: Prazo de Atendimento
A17: Qualidade dos serviços executados
A18: Discrição e Presteza dos funcionários
A19: RESUMO DO ORÇAMENTO DOS SERVIÇOS EXECUTADOS
A20: Data / Hora Conclusão | F20: Valor de Materiais + Mão de Obra | I20: Valor Total
A21: =RAT!B53 -> 46078 | F21: =RAT!G53 -> #N/A | G21: + | H21: =RAT!I53 -> #N/A | I21: =RAT!J53 -> #N/A
A22: Observações
A24: Sr. ADMINISTRADOR PREDIAL, antes de assinar o RAT (Relatório de Atendimento), deve-se observar que:
A25: 1. A Situação (código, em "Serviços Solicitados") foi preenchida adequadamente para cada serviço solicitado e que os serviços
A26: registrados como concluídos, ficaram sem pendências;
A27: 2. Os serviços solicitados, porém não executados ou executados parcialmente, tiveram um valor descontado no campo "Resumo do Orçamento dos
A28: Serviços Executados".
A29: 3. O documento deverá ser totalmente preenchido, em todos os campos e sem rasuras. Inutilizar os espaços em branco;
A30: 4. A segunda via do RAT deverá ficar arquivada na dependência beneficiária para consultas futuras;
A31: 5. Deve-se registrar no Portal de Manutenção da DISEC as informações contidas no RAT.
A32: Dúvidas quanto aos itens, quantitativos e valores aplicados aos serviços, deverão ser sanadas com a CONTRATADA durante o atendimento. Caso não
A33: ocorra o esclarecimento, consultar o CESUP SUPRIMENTOS.
A34: Lembramos que o ADMINISTRADOR PREDIAL é o responsável pela fiscalização dos serviços executados na dependência e que a
... A36: dos serviços
B38: ________________________________________________ | H38: ___________________________________________________________________________________
B39: VISTO REPRESENTANTE DA EMPRESA CONTRATADA | H39: CARIMBO E VISTO DA DEPENDÊNCIA
A41: Parecer do Responsável Técnico / Contratada | I41: ENGENHEIRO
I47: CARIMBO - NÚMERO / VISTO DO CREA
A48: O RAT deverá ser emitido em 3 vias, sendo: a 1° Depêndencia Beneficiária, 2° Empresa Contratada, e em 3° CESUP Suprimentos

Sheet Valores
B1: A interessada deverá prrencher os campos em amarelo abaixo.
C3: CONSERVAÇÃO PREDIAL | M3: Informar nos campos em amarelo abaixo o desconto para MA e MO. Poderá ser informado desconto diferente ou igual para MA e MO de forma a ajustar o desconto global ao desconto ofertado na licitação. O campo em verde, após o preenchimento do MA, MO e BDI (em sua respectiva aba), deverá refletir o valor de desconto ofertado na Licitação. O valor efetivo de desconto de MA e MO considerando BDI aparecerá nos campos em Azul.
B4: PROPONENTE : | G4: LOTE: | H4: 03 | M4: Material sem BDI | N4: Mão de obra sem BDI
B5: MAFFENG ENGENHARIA E MANUTENÇÃO LTDA | C5: CNPJ: | D5: 33624704/0001-94 | I5: DESCONTO: | J5: =N7 -> 0.37860761 | M5: 0.3786 | N5: 0.3786 | V5: Não mexer nos dados abaixo. Dados Sem BDI. | AB5: Não mexer nos dados abaixo. Dados com BDI. | AH5: Descontos Calculados
A7: ITEM | C7: QTDE | D7: UN. | E7: UNITÁRIO MATERIAL | F7: UNITÁRIO MÃO DE OBRA | G7: TOTAL UNITÁRIO DO ITEM | H7: TOTAL MATERIAL ROTEIRO | I7: TOTAL MÃO DE OBRA ROTEIRO | J7: TOTAL GERAL ROTEIRO | M7: Desconto Global Calculado com BDI | N7: =1-(J537/AF537) -> 0.37860761 | V7: QTDE | W7: UN. | X7: UNITÁRIO MATERIAL Referência | Y7: UNITÁRIO MÃO DE OBRA Referência | Z7: TOTAL UNITÁRIO DO ITEM Referência | AB7: QTDE | AC7: UN. | AD7: UNITÁRIO MATERIAL Referência | AE7: UNITÁRIO MÃO DE OBRA Referência | AF7: TOTAL UNITÁRIO DO ITEM Referência | AH7: UNITÁRIO MATERIAL Referência | AI7: UNITÁRIO MÃO DE OBRA Referência | AJ7: TOTAL UNITÁRIO DO ITEM Referência
A8: 1 | B8: PRELIMINARES | H8: =SUM(H9:H15) -> 523740.87 | I8: =SUM(I9:I15) -> 204215.58 | J8: =SUM(J9:J15) -> 727956.45 | M8: O valor do campo em verde deverá ser igual ao da proposta apresentada.
A9: 1.1 | B9: Chamado | C9: =V9 -> 286 | D9: =W9 -> un | E9: =ROUND((X9*(1-$M$5))*(1+BDI!$C$21),2) -> 0 | F9: =ROUND((Y9*(1-$N$5))*(1+BDI!$C$21),2) -> 76.34 | G9: =F9+E9 -> 76.34 | H9: =C9*E9 -> 0 | I9: =C9*F9 -> 21833.24 | J9: =SUM(E9:F9)*C9 -> 21833.24 | V9: 286 | W9: un | X9: 0 | Y9: 95.37 | Z9: =SUM(X9:Y9) -> 95.37 | AB9: 286 | AC9: un | AD9: 0 | AE9: 122.86 | AF9: =SUM(AD9:AE9) -> 122.86 | AH9: =IF(E9=0,0,(E9/AD9)-1) -> 0 | AI9: =IF(F9=0,0,(F9/AE9)-1) -> -0.37864236 | AJ9: =IF(G9=0,0,(G9/AF9)-1) -> -0.37864236
A10: 1.2 | B10: Deslocamento | C10: =V10 -> 213840 | D10: =W10 -> km | E10: =ROUND((X10*(1-$M$5))*(1+BDI!$C$21),2) -> 1.51 | F10: =ROUND((Y10*(1-$N$5))*(1+BDI!$C$21),2) -> 0.64 | G10: =F10+E10 -> 2.15 | H10: =C10*E10 -> 322898.4 | I10: =C10*F10 -> 136857.6 | J10: =SUM(E10:F10)*C10 -> 459756 | V10: 213840 | W10: km | X10: 1.89 | Y10: 0.8 | Z10: =SUM(X10:Y10) -> 2.69 | AB10: 213840 | AC10: km | AD10: 2.43 | AE10: 1.03 | AF10: =SUM(AD10:AE10) -> 3.46 | AH10: =IF(E10=0,0,(E10/AD10)-1) -> -0.37860082 | AI10: =IF(F10=0,0,(F10/AE10)-1) -> -0.37864078 | AJ10: =IF(G10=0,0,(G10/AF10)-1) -> -0.37861272
A11: 1.3 | B11: Revisão de instalações | C11: =V11 -> 108 | D11: =W11 -> un | E11: =ROUND((X11*(1-$M$5))*(1+BDI!$C$21),2) -> 79.76 | F11: =ROUND((Y11*(1-$N$5))*(1+BDI!$C$21),2) -> 412.76 | G11: =F11+E11 -> 492.52 | H11: =C11*E11 -> 8614.08 | I11: =C11*F11 -> 44578.08 | J11: =SUM(E11:F11)*C11 -> 53192.16 | V11: 108 | W11: un | X11: 99.64 | Y11: 515.64 | Z11: =SUM(X11:Y11) -> 615.28 | AB11: 108 | AC11: un | AD11: 128.36 | AE11: 664.25 | AF11: =SUM(AD11:AE11) -> 792.61 | AH11: =IF(E11=0,0,(E11/AD11)-1) -> -0.37862262 | AI11: =IF(F11=0,0,(F11/AE11)-1) -> -0.37860745 | AJ11: =IF(G11=0,0,(G11/AF11)-1) -> -0.37860991
A12: 1.4 | B12: Acompanhamento técnico em Segurança do Trabalho | C12: =V12 -> 1 | D12: =W12 -> un | E12: =ROUND((X12*(1-$M$5))*(1+BDI!$C$21),2) -> 0 | F12: =ROUND((Y12*(1-$N$5))*(1+BDI!$C$21),2) -> 389.42 | G12: =F12+E12 -> 389.42 | H12: =C12*E12 -> 0 | I12: =C12*F12 -> 389.42 | J12: =SUM(E12:F12)*C12 -> 389.42 | V12: 1 | W12: un | X12: 0 | Y12: 486.48 | Z12: =SUM(X12:Y12) -> 486.48 | AB12: 1 | AC12: un | AD12: 0 | AE12: 626.68 | AF12: =SUM(AD12:AE12) -> 626.68 | AH12: =IF(E12=0,0,(E12/AD12)-1) -> 0 | AI12: =IF(F12=0,0,(F12/AE12)-1) -> -0.37859833 | AJ12: =IF(G12=0,0,(G12/AF12)-1) -> -0.37859833
A13: 1.5 | B13: Hospedagem de equipe técnica - Serviços prolongados | C13: =V13 -> 108 | D13: =W13 -> un | E13: =ROUND((X13*(1-$M$5))*(1+BDI!$C$21),2) -> 1779.12 | F13: =ROUND((Y13*(1-$N$5))*(1+BDI!$C$21),2) -> 0 | G13: =F13+E13 -> 1779.12 | H13: =C13*E13 -> 192144.96 | I13: =C13*F13 -> 0 | J13: =SUM(E13:F13)*C13 -> 192144.96 | V13: 108 | W13: un | X13: 2222.54 | Y13: 0 | Z13: =SUM(X13:Y13) -> 2222.54 | AB13: 108 | AC13: un | AD13: 2863.08 | AE13: 0 | AF13: =SUM(AD13:AE13) -> 2863.08 | AH13: =IF(E13=0,0,(E13/AD13)-1) -> -0.37859927 | AI13: =IF(F13=0,0,(F13/AE13)-1) -> 0 | AJ13: =IF(G13=0,0,(G13/AF13)-1) -> -0.37859927
A14: 1.6 | B14: Deslocamento Fluvial | C14: =V14 -> 1 | D14: =W14 -> Km | E14: =ROUND((X14*(1-$M$5))*(1+BDI!$C$21),2) -> 0.75 | F14: =ROUND((Y14*(1-$N$5))*(1+BDI!$C$21),2) -> 1.58 | G14: =F14+E14 -> 2.33 | H14: =C14*E14 -> 0.75 | I14: =C14*F14 -> 1.58 | J14: =SUM(E14:F14)*C14 -> 2.33 | M14: Desconto Calculado Material Efetivo | N14: =IF(M5=0,0,ROUND(AH540,4)) -> -0.3786 | V14: 1 | W14: Km | X14: 0.94 | Y14: 1.97 | Z14: =SUM(X14:Y14) -> 2.91 | AB14: 1 | AC14: Km | AD14: 1.21 | AE14: 2.54 | AF14: =SUM(AD14:AE14) -> 3.75 | AH14: =IF(E14=0,0,(E14/AD14)-1) -> -0.38016529 | AI14: =IF(F14=0,0,(F14/AE14)-1) -> -0.37795276 | AJ14: =IF(G14=0,0,(G14/AF14)-1) -> -0.37866667
A15: 1.7 | B15: Laudo técnico fotográfico - Elementos de Sinalização - Padrão BB | C15: =V15 -> 1 | D15: =W15 -> UN | E15: =ROUND((X15*(1-$M$5))*(1+BDI!$C$21),2) -> 82.68 | F15: =ROUND((Y15*(1-$N$5))*(1+BDI!$C$21),2) -> 555.66 | G15: =F15+E15 -> 638.34 | H15: =C15*E15 -> 82.68 | I15: =C15*F15 -> 555.66 | J15: =SUM(E15:F15)*C15 -> 638.34 | M15: Desconto Calculado Mão de Obra Efetivo | N15: =IF(N5=0,0,ROUND(AI540,4)) -> -0.3786 | V15: 1 | W15: UN | X15: 103.29 | Y15: 694.15 | Z15: =SUM(X15:Y15) -> 797.44 | AB15: 1 | AC15: UN | AD15: 133.06 | AE15: 894.2 | AF15: =SUM(AD15:AE15) -> 1027.26 | AH15: =IF(E15=0,0,(E15/AD15)-1) -> -0.37862618 | AI15: =IF(F15=0,0,(F15/AE15)-1) -> -0.37859539 | AJ15: =IF(G15=0,0,(G15/AF15)-1) -> -0.37859938
A16: 2 | B16: IMPLANTAÇÃO / ADMINISTRAÇÃO | H16: =SUM(H17:H52) -> 101208.4 | I16: =SUM(I17:I52) -> 134610.64 | J16: =SUM(J17:J52) -> 235819.04 | M16: Os valores acima consideram o valor informado na aba BDI. | AH16: =IF(E16=0,0,(E16/AD16)-1) -> 0 | AI16: =IF(F16=0,0,(F16/AE16)-1) -> 0 | AJ16: =IF(G16=0,0,(G16/AF16)-1) -> 0
A17: 2.1 | B17: Demolição manual de concreto simples | C17: =V17 -> 24 | D17: =W17 -> m³ | E17: =ROUND((X17*(1-$M$5))*(1+BDI!$C$21),2) -> 0 | F17: =ROUND((Y17*(1-$N$5))*(1+BDI!$C$21),2) -> 306.35 | G17: =F17+E17 -> 306.35 | H17: =C17*E17 -> 0 | I17: =C17*F17 -> 7352.4 | J17: =SUM(E17:F17)*C17 -> 7352.4 | V17: 24 | W17: m³ | X17: 0 | Y17: 382.71 | Z17: =SUM(X17:Y17) -> 382.71 | AB17: 24 | AC17: m³ | AD17: 0 | AE17: 493.01 | AF17: =SUM(AD17:AE17) -> 493.01 | AH17: =IF(E17=0,0,(E17/AD17)-1) -> 0 | AI17: =IF(F17=0,0,(F17/AE17)-1) -> -0.37861301 | AJ17: =IF(G17=0,0,(G17/AF17)-1) -> -0.37861301
A18: 2.2 | B18: Demolição manual de alvenaria de elevação ou elemento vazado, incluindo revestimento | C18: =V18 -> 43 | D18: =W18 -> m³ | E18: =ROUND((X18*(1-$M$5))*(1+BDI!$C$21),2) -> 0 | F18: =ROUND((Y18*(1-$N$5))*(1+BDI!$C$21),2) -> 70.7 | G18: =F18+E18 -> 70.7 | H18: =C18*E18 -> 0 | I18: =C18*F18 -> 3040.1 | J18: =SUM(E18:F18)*C18 -> 3040.1 | M18: A interessada pode alterar o BDI na respectiva aba da planilha eletrônica. A alteração do BDI afeta o desconto calculado efetivo de material e de mão de obra. O valor do BDI deverá ser igual ao da proposta a ser apresentada. | V18: 43 | W18: m³ | X18: 0 | Y18: 88.32 | Z18: =SUM(X18:Y18) -> 88.32 | AB18: 43 | AC18: m³ | AD18: 0 | AE18: 113.77 | AF18: =SUM(AD18:AE18) -> 113.77 | AH18: =IF(E18=0,0,(E18/AD18)-1) -> 0 | AI18: =IF(F18=0,0,(F18/AE18)-1) -> -0.3785708 | AJ18: =IF(G18=0,0,(G18/AF18)-1) -> -0.3785708
A19: 2.3 | B19: Demolição manual de revestimento em massa de parede ou teto ou Dry-Wall | C19: =V19 -> 308 | D19: =W19 -> m³ | E19: =ROUND((X19*(1-$M$5))*(1+BDI!$C$21),2) -> 0 | F19: =ROUND((Y19*(1-$N$5))*(1+BDI!$C$21),2) -> 7.5 | G19: =F19+E19 -> 7.5 | H19: =C19*E19 -> 0 | I19: =C19*F19 -> 2310 | J19: =SUM(E19:F19)*C19 -> 2310 | V19: 308 | W19: m³ | X19: 0 | Y19: 9.37 | Z19: =SUM(X19:Y19) -> 9.37 | AB19: 308 | AC19: m³ | AD19: 0 | AE19: 12.07 | AF19: =SUM(AD19:AE19) -> 12.07 | AH19: =IF(E19=0,0,(E19/AD19)-1) -> 0 | AI19: =IF(F19=0,0,(F19/AE19)-1) -> -0.37862469 | AJ19: =IF(G19=0,0,(G19/AF19)-1) -> -0.37862469
A20: 2.4 | B20: Demolição de pisos em geral (ladrilho hidráulico, camada de enchimento, cerâmica, porcelanato, mármore, granito, pedra e madeira) - Manual | C20: =V20 -> 247 | D20: =W20 -> m² | E20: =ROUND((X20*(1-$M$5))*(1+BDI!$C$21),2) -> 0 | F20: =ROUND((Y20*(1-$N$5))*(1+BDI!$C$21),2) -> 32.99 | G20: =F20+E20 -> 32.99 | H20: =C20*E20 -> 0 | I20: =C20*F20 -> 8148.53 | J20: =SUM(E20:F20)*C20 -> 8148.53 | V20: 247 | W20: m² | X20: 0 | Y20: 41.21 | Z20: =SUM(X20:Y20) -> 41.21 | AB20: 247 | AC20: m² | AD20: 0 | AE20: 53.09 | AF20: =SUM(AD20:AE20) -> 53.09 | AH20: =IF(E20=0,0,(E20/AD20)-1) -> 0 | AI20: =IF(F20=0,0,(F20/AE20)-1) -> -0.37860237 | AJ20: =IF(G20=0,0,(G20/AF20)-1) -> -0.37860237
A21: 2.5 | B21: Demolição de pisos em geral (ladrilho hidráulico, camada de enchimento, cerâmica, porcelanato, mármore, granito, pedra e madeira) - Mecanizado | C21: =V21 -> 96 | D21: =W21 -> m² | E21: =ROUND((X21*(1-$M$5))*(1+BDI!$C$21),2) -> 24.01 | F21: =ROUND((Y21*(1-$N$5))*(1+BDI!$C$21),2) -> 16.5 | G21: =F21+E21 -> 40.51 | H21: =C21*E21 -> 2304.96 | I21: =C21*F21 -> 1584 | J21: =SUM(E21:F21)*C21 -> 3888.96 | V21: 96 | W21: m² | X21: 30 | Y21: 20.61 | Z21: =SUM(X21:Y21) -> 50.61 | AB21: 96 | AC21: m² | AD21: 38.65 | AE21: 26.55 | AF21: =SUM(AD21:AE21) -> 65.2 | AH21: =IF(E21=0,0,(E21/AD21)-1) -> -0.37878396 | AI21: =IF(F21=0,0,(F21/AE21)-1) -> -0.37853107 | AJ21: =IF(G21=0,0,(G21/AF21)-1) -> -0.37868098
A22: 2.6 | B22: Demolição de pavimentação com pré-moldado de concreto ou intertravado | C22: =V22 -> 6 | D22: =W22 -> m² | E22: =ROUND((X22*(1-$M$5))*(1+BDI!$C$21),2) -> 0 | F22: =ROUND((Y22*(1-$N$5))*(1+BDI!$C$21),2) -> 16.5 | G22: =F22+E22 -> 16.5 | H22: =C22*E22 -> 0 | I22: =C22*F22 -> 99 | J22: =SUM(E22:F22)*C22 -> 99 | V22: 6 | W22: m² | X22: 0 | Y22: 20.61 | Z22: =SUM(X22:Y22) -> 20.61 | AB22: 6 | AC22: m² | AD22: 0 | AE22: 26.55 | AF22: =SUM(AD22:AE22) -> 26.55 | AH22: =IF(E22=0,0,(E22/AD22)-1) -> 0 | AI22: =IF(F22=0,0,(F22/AE22)-1) -> -0.37853107 | AJ22: =IF(G22=0,0,(G22/AF22)-1) -> -0.37853107
A23: 2.7 | B23: Demolição de piso cimentado sobre lastro de concreto | C23: =V23 -> 35 | D23: =W23 -> m² | E23: =ROUND((X23*(1-$M$5))*(1+BDI!$C$21),2) -> 0 | F23: =ROUND((Y23*(1-$N$5))*(1+BDI!$C$21),2) -> 30.63 | G23: =F23+E23 -> 30.63 | H23: =C23*E23 -> 0 | I23: =C23*F23 -> 1072.05 | J23: =SUM(E23:F23)*C23 -> 1072.05 | V23: 35 | W23: m² | X23: 0 | Y23: 38.27 | Z23: =SUM(X23:Y23) -> 38.27 | AB23: 35 | AC23: m² | AD23: 0 | AE23: 49.3 | AF23: =SUM(AD23:AE23) -> 49.3 | AH23: =IF(E23=0,0,(E23/AD23)-1) -> 0 | AI23: =IF(F23=0,0,(F23/AE23)-1) -> -0.37870183 | AJ23: =IF(G23=0,0,(G23/AF23)-1) -> -0.37870183
A24: 2.8 | B24: Demolição manual de forro, inclusive sistema de fixação/tarugamento | C24: =V24 -> 794 | D24: =W24 -> m² | E24: =ROUND((X24*(1-$M$5))*(1+BDI!$C$21),2) -> 0 | F24: =ROUND((Y24*(1-$N$5))*(1+BDI!$C$21),2) -> 9.43 | G24: =F24+E24 -> 9.43 | H24: =C24*E24 -> 0 | I24: =C24*F24 -> 7487.42 | J24: =SUM(E24:F24)*C24 -> 7487.42 | M24: A interessada pode utilizar modelo próprio de planilha para cálculo,entretanto,a planilha final a ser apresentada juntamente com a proposta, deverá ter a mesma formatação do orçamento estimado que compõe a licitação. | V24: 794 | W24: m² | X24: 0 | Y24: 11.78 | Z24: =SUM(X24:Y24) -> 11.78 | AB24: 794 | AC24: m² | AD24: 0 | AE24: 15.17 | AF24: =SUM(AD24:AE24) -> 15.17 | AH24: =IF(E24=0,0,(E24/AD24)-1) -> 0 | AI24: =IF(F24=0,0,(F24/AE24)-1) -> -0.37837838 | AJ24: =IF(G24=0,0,(G24/AF24)-1) -> -0.37837838
A25: 2.9 | B25: Demolição de contrapiso/argamassa regularizante, isolante ou protetora | C25: =V25 -> 172 | D25: =W25 -> m² | E25: =ROUND((X25*(1-$M$5))*(1+BDI!$C$21),2) -> 0 | F25: =ROUND((Y25*(1-$N$5))*(1+BDI!$C$21),2) -> 11.78 | G25: =F25+E25 -> 11.78 | H25: =C25*E25 -> 0 | I25: =C25*F25 -> 2026.16 | J25: =SUM(E25:F25)*C25 -> 2026.16 | V25: 172 | W25: m² | X25: 0 | Y25: 14.72 | Z25: =SUM(X25:Y25) -> 14.72 | AB25: 172 | AC25: m² | AD25: 0 | AE25: 18.96 | AF25: =SUM(AD25:AE25) -> 18.96 | AH25: =IF(E25=0,0,(E25/AD25)-1) -> 0 | AI25: =IF(F25=0,0,(F25/AE25)-1) -> -0.37869198 | AJ25: =IF(G25=0,0,(G25/AF25)-1) -> -0.37869198
A26: 2.10 | B26: Demolição de estrutura em madeira para telhado | C26: =V26 -> 52 | D26: =W26 -> m² | E26: =ROUND((X26*(1-$M$5))*(1+BDI!$C$21),2) -> 0 | F26: =ROUND((Y26*(1-$N$5))*(1+BDI!$C$21),2) -> 32.56 | G26: =F26+E26 -> 32.56 | H26: =C26*E26 -> 0 | I26: =C26*F26 -> 1693.12 | J26: =SUM(E26:F26)*C26 -> 1693.12 | V26: 52 | W26: m² | X26: 0 | Y26: 40.68 | Z26: =SUM(X26:Y26) -> 40.68 | AB26: 52 | AC26: m² | AD26: 0 | AE26: 52.4 | AF26: =SUM(AD26:AE26) -> 52.4 | AH26: =IF(E26=0,0,(E26/AD26)-1) -> 0 | AI26: =IF(F26=0,0,(F26/AE26)-1) -> -0.37862595 | AJ26: =IF(G26=0,0,(G26/AF26)-1) -> -0.37862595
A27: 2.11 | B27: Retirada de cumeeira, espigão, rufo, calha ou chapim, perfil qualquer | C27: =V27 -> 137 | D27: =W27 -> m | E27: =ROUND((X27*(1-$M$5))*(1+BDI!$C$21),2) -> 0 | F27: =ROUND((Y27*(1-$N$5))*(1+BDI!$C$21),2) -> 15.21 | G27: =F27+E27 -> 15.21 | H27: =C27*E27 -> 0 | I27: =C27*F27 -> 2083.77 | J27: =SUM(E27:F27)*C27 -> 2083.77 | V27: 137 | W27: m | X27: 0 | Y27: 19 | Z27: =SUM(X27:Y27) -> 19 | AB27: 137 | AC27: m | AD27: 0 | AE27: 24.48 | AF27: =SUM(AD27:AE27) -> 24.48 | AH27: =IF(E27=0,0,(E27/AD27)-1) -> 0 | AI27: =IF(F27=0,0,(F27/AE27)-1) -> -0.37867647 | AJ27: =IF(G27=0,0,(G27/AF27)-1) -> -0.37867647
A28: 2.12 | B28: Retirada de piso tátil com limpeza | C28: =V28 -> 564 | D28: =W28 -> m² | E28: =ROUND((X28*(1-$M$5))*(1+BDI!$C$21),2) -> 10.11 | F28: =ROUND((Y28*(1-$N$5))*(1+BDI!$C$21),2) -> 24.78 | G28: =F28+E28 -> 34.89 | H28: =C28*E28 -> 5702.04 | I28: =C28*F28 -> 13975.92 | J28: =SUM(E28:F28)*C28 -> 19677.96 | V28: 564 | W28: m² | X28: 12.63 | Y28: 30.95 | Z28: =SUM(X28:Y28) -> 43.58 | AB28: 564 | AC28: m² | AD28: 16.27 | AE28: 39.87 | AF28: =SUM(AD28:AE28) -> 56.14 | AH28: =IF(E28=0,0,(E28/AD28)-1) -> -0.37861094 | AI28: =IF(F28=0,0,(F28/AE28)-1) -> -0.37848006 | AJ28: =IF(G28=0,0,(G28/AF28)-1) -> -0.37851799
A29: 2.13 | B29: Remoção de revestimento de piso de carpete ou manta vinílica | C29: =V29 -> 1626 | D29: =W29 -> m² | E29: =ROUND((X29*(1-$M$5))*(1+BDI!$C$21),2) -> 10.11 | F29: =ROUND((Y29*(1-$N$5))*(1+BDI!$C$21),2) -> 12.54 | G29: =F29+E29 -> 22.65 | H29: =C29*E29 -> 16438.86 | I29: =C29*F29 -> 20390.04 | J29: =SUM(E29:F29)*C29 -> 36828.9 | V29: 1626 | W29: m² | X29: 12.63 | Y29: 15.66 | Z29: =SUM(X29:Y29) -> 28.29 | AB29: 1626 | AC29: m² | AD29: 16.27 | AE29: 20.17 | AF29: =SUM(AD29:AE29) -> 36.44 | AH29: =IF(E29=0,0,(E29/AD29)-1) -> -0.37861094 | AI29: =IF(F29=0,0,(F29/AE29)-1) -> -0.37828458 | AJ29: =IF(G29=0,0,(G29/AF29)-1) -> -0.3784303
A30: 2.14 | B30: Ajuste de Piso Elevado (remoção e recolocação de revestimentos e placas do piso inclusive) | C30: =V30 -> 49 | D30: =W30 -> m² | E30: =ROUND((X30*(1-$M$5))*(1+BDI!$C$21),2) -> 7.18 | F30: =ROUND((Y30*(1-$N$5))*(1+BDI!$C$21),2) -> 65.25 | G30: =F30+E30 -> 72.43 | H30: =C30*E30 -> 351.82 | I30: =C30*F30 -> 3197.25 | J30: =SUM(E30:F30)*C30 -> 3549.07 | V30: 49 | W30: m² | X30: 8.97 | Y30: 81.51 | Z30: =SUM(X30:Y30) -> 90.48 | AB30: 49 | AC30: m² | AD30: 11.56 | AE30: 105 | AF30: =SUM(AD30:AE30) -> 116.56 | AH30: =IF(E30=0,0,(E30/AD30)-1) -> -0.37889273 | AI30: =IF(F30=0,0,(F30/AE30)-1) -> -0.37857143 | AJ30: =IF(G30=0,0,(G30/AF30)-1) -> -0.37860329
A31: 2.15 | B31: Retirada de piso elevado, inclusive estrutura de sustentação | C31: =V31 -> 153 | D31: =W31 -> m² | E31: =ROUND((X31*(1-$M$5))*(1+BDI!$C$21),2) -> 0 | F31: =ROUND((Y31*(1-$N$5))*(1+BDI!$C$21),2) -> 30.06 | G31: =F31+E31 -> 30.06 | H31: =C31*E31 -> 0 | I31: =C31*F31 -> 4599.18 | J31: =SUM(E31:F31)*C31 -> 4599.18 | V31: 153 | W31: m² | X31: 0 | Y31: 37.55 | Z31: =SUM(X31:Y31) -> 37.55 | AB31: 153 | AC31: m² | AD31: 0 | AE31: 48.37 | AF31: =SUM(AD31:AE31) -> 48.37 | AH31: =IF(E31=0,0,(E31/AD31)-1) -> 0 | AI31: =IF(F31=0,0,(F31/AE31)-1) -> -0.37854042 | AJ31: =IF(G31=0,0,(G31/AF31)-1) -> -0.37854042
A32: 2.16 | B32: Reinstalação de piso elevado proveniente de reaproveitamento, incluso material | C32: =V32 -> 12 | D32: =W32 -> m² | E32: =ROUND((X32*(1-$M$5))*(1+BDI!$C$21),2) -> 1.42 | F32: =ROUND((Y32*(1-$N$5))*(1+BDI!$C$21),2) -> 70.72 | G32: =F32+E32 -> 72.14 | H32: =C32*E32 -> 17.04 | I32: =C32*F32 -> 848.64 | J32: =SUM(E32:F32)*C32 -> 865.68 | V32: 12 | W32: m² | X32: 1.77 | Y32: 88.35 | Z32: =SUM(X32:Y32) -> 90.12 | AB32: 12 | AC32: m² | AD32: 2.28 | AE32: 113.81 | AF32: =SUM(AD32:AE32) -> 116.09 | AH32: =IF(E32=0,0,(E32/AD32)-1) -> -0.37719298 | AI32: =IF(F32=0,0,(F32/AE32)-1) -> -0.37861348 | AJ32: =IF(G32=0,0,(G32/AF32)-1) -> -0.37858558
A33: 2.17 | B33: Retirada ou recolocação de vidro | C33: =V33 -> 358 | D33: =W33 -> m² | E33: =ROUND((X33*(1-$M$5))*(1+BDI!$C$21),2) -> 10.33 | F33: =ROUND((Y33*(1-$N$5))*(1+BDI!$C$21),2) -> 16.84 | G33: =F33+E33 -> 27.17 | H33: =C33*E33 -> 3698.14 | I33: =C33*F33 -> 6028.72 | J33: =SUM(E33:F33)*C33 -> 9726.86 | V33: 358 | W33: m² | X33: 12.9 | Y33: 21.04 | Z33: =SUM(X33:Y33) -> 33.94 | AB33: 358 | AC33: m² | AD33: 16.62 | AE33: 27.1 | AF33: =SUM(AD33:AE33) -> 43.72 | AH33: =IF(E33=0,0,(E33/AD33)-1) -> -0.37845969 | AI33: =IF(F33=0,0,(F33/AE33)-1) -> -0.37859779 | AJ33: =IF(G33=0,0,(G33/AF33)-1) -> -0.37854529
A34: 2.18 | B34: Remoção de entulho com caçamba metálica, inclusive limpeza, transporte, carga, descarga e descarte conforme legislação ambiental - Material de descarte (alvenaria, estruturas metálicas, madeiramento, revestimentos cerâmicos, gesso, dry-wall, entre outros) | C34: =V34 -> 694 | D34: =W34 -> m³ | E34: =ROUND((X34*(1-$M$5))*(1+BDI!$C$21),2) -> 50.35 | F34: =ROUND((Y34*(1-$N$5))*(1+BDI!$C$21),2) -> 14.8 | G34: =F34+E34 -> 65.15 | H34: =C34*E34 -> 34942.9 | I34: =C34*F34 -> 10271.2 | J34: =SUM(E34:F34)*C34 -> 45214.1 | V34: 694 | W34: m³ | X34: 62.9 | Y34: 18.49 | Z34: =SUM(X34:Y34) -> 81.39 | AB34: 694 | AC34: m³ | AD34: 81.03 | AE34: 23.82 | AF34: =SUM(AD34:AE34) -> 104.85 | AH34: =IF(E34=0,0,(E34/AD34)-1) -> -0.3786252 | AI34: =IF(F34=0,0,(F34/AE34)-1) -> -0.37867338 | AJ34: =IF(G34=0,0,(G34/AF34)-1) -> -0.37863615
A35: 2.19 | B35: Remoção / Remanejamento de placa aérea | C35: =V35 -> 150 | D35: =W35 -> un | E35: =ROUND((X35*(1-$M$5))*(1+BDI!$C$21),2) -> 3.14 | F35: =ROUND((Y35*(1-$N$5))*(1+BDI!$C$21),2) -> 45.55 | G35: =F35+E35 -> 48.69 | H35: =C35*E35 -> 471 | I35: =C35*F35 -> 6832.5 | J35: =SUM(E35:F35)*C35 -> 7303.5 | V35: 150 | W35: un | X35: 3.92 | Y35: 56.9 | Z35: =SUM(X35:Y35) -> 60.82 | AB35: 150 | AC35: un | AD35: 5.05 | AE35: 73.3 | AF35: =SUM(AD35:AE35) -> 78.35 | AH35: =IF(E35=0,0,(E35/AD35)-1) -> -0.37821782 | AI35: =IF(F35=0,0,(F35/AE35)-1) -> -0.37858117 | AJ35: =IF(G35=0,0,(G35/AF35)-1) -> -0.37855775
A36: 2.20 | B36: Andaime tubular fachadeiro | C36: =V36 -> 202 | D36: =W36 -> m²/mês | E36: =ROUND((X36*(1-$M$5))*(1+BDI!$C$21),2) -> 17.31 | F36: =ROUND((Y36*(1-$N$5))*(1+BDI!$C$21),2) -> 7.34 | G36: =F36+E36 -> 24.65 | H36: =C36*E36 -> 3496.62 | I36: =C36*F36 -> 1482.68 | J36: =SUM(E36:F36)*C36 -> 4979.3 | V36: 202 | W36: m²/mês | X36: 21.63 | Y36: 9.17 | Z36: =SUM(X36:Y36) -> 30.8 | AB36: 202 | AC36: m²/mês | AD36: 27.86 | AE36: 11.81 | AF36: =SUM(AD36:AE36) -> 39.67 | AH36: =IF(E36=0,0,(E36/AD36)-1) -> -0.37867911 | AI36: =IF(F36=0,0,(F36/AE36)-1) -> -0.3784928 | AJ36: =IF(G36=0,0,(G36/AF36)-1) -> -0.37862365
... A52: 2.36 | B52: Tela para Andaime | C52: =V52 -> 1 | D52: =W52 -> m² | E52: =ROUND((X52*(1-$M$5))*(1+BDI!$C$21),2) -> 2.1 | F52: =ROUND((Y52*(1-$N$5))*(1+BDI!$C$21),2) -> 3.34 | G52: =F52+E52 -> 5.44 | H52: =C52*E52 -> 2.1 | I52: =C52*F52 -> 3.34 | J52: =SUM(E52:F52)*C52 -> 5.44 | V52: 1 | W52: m² | X52: 2.62 | Y52: 4.17 | Z52: =SUM(X52:Y52) -> 6.79 | AB52: 1 | AC52: m² | AD52: 3.38 | AE52: 5.37 | AF52: =SUM(AD52:AE52) -> 8.75 | AH52: =IF(E52=0,0,(E52/AD52)-1) -> -0.37869822 | AI52: =IF(F52=0,0,(F52/AE52)-1) -> -0.37802607 | AJ52: =IF(G52=0,0,(G52/AF52)-1) -> -0.37828571
A53: 3 | B53: MOVIMENTO DE TERRA | H53: =SUM(H54:H55) -> 1.89 | I53: =SUM(I54:I55) -> 103.23 | J53: =SUM(J54:J55) -> 105.12 | AH53: =IF(E53=0,0,(E53/AD53)-1) -> 0 | AI53: =IF(F53=0,0,(F53/AE53)-1) -> 0 | AJ53: =IF(G53=0,0,(G53/AF53)-1) -> 0
A54: 3.1 | B54: Escavação Manual em Solo | C54: =V54 -> 1 | D54: =W54 -> m³ | E54: =ROUND((X54*(1-$M$5))*(1+BDI!$C$21),2) -> 0 | F54: =ROUND((Y54*(1-$N$5))*(1+BDI!$C$21),2) -> 84.6 | G54: =F54+E54 -> 84.6 | H54: =C54*E54 -> 0 | I54: =C54*F54 -> 84.6 | J54: =SUM(E54:F54)*C54 -> 84.6 | V54: 1 | W54: m³ | X54: 0 | Y54: 105.68 | Z54: =SUM(X54:Y54) -> 105.68 | AB54: 1 | AC54: m³ | AD54: 0 | AE54: 136.14 | AF54: =SUM(AD54:AE54) -> 136.14 | AH54: =IF(E54=0,0,(E54/AD54)-1) -> 0 | AI54: =IF(F54=0,0,(F54/AE54)-1) -> -0.37858087 | AJ54: =IF(G54=0,0,(G54/AF54)-1) -> -0.37858087
A55: 3.2 | B55: Reaterro/Aterro Manual de Solo | C55: =V55 -> 1 | D55: =W55 -> m³ | E55: =ROUND((X55*(1-$M$5))*(1+BDI!$C$21),2) -> 1.89 | F55: =ROUND((Y55*(1-$N$5))*(1+BDI!$C$21),2) -> 18.63 | G55: =F55+E55 -> 20.52 | H55: =C55*E55 -> 1.89 | I55: =C55*F55 -> 18.63 | J55: =SUM(E55:F55)*C55 -> 20.52 | V55: 1 | W55: m³ | X55: 2.36 | Y55: 23.27 | Z55: =SUM(X55:Y55) -> 25.63 | AB55: 1 | AC55: m³ | AD55: 3.04 | AE55: 29.98 | AF55: =SUM(AD55:AE55) -> 33.02 | AH55: =IF(E55=0,0,(E55/AD55)-1) -> -0.37828947 | AI55: =IF(F55=0,0,(F55/AE55)-1) -> -0.37858572 | AJ55: =IF(G55=0,0,(G55/AF55)-1) -> -0.37855845
A56: 4 | B56: FUNDAÇÃO | H56: 0 | I56: 0 | J56: 0 | AH56: =IF(E56=0,0,(E56/AD56)-1) -> 0 | AI56: =IF(F56=0,0,(F56/AE56)-1) -> 0 | AJ56: =IF(G56=0,0,(G56/AF56)-1) -> 0
A57: 5 | B57: ESTRUTURA | H57: =SUM(H58:H61) -> 10931.85 | I57: =SUM(I58:I61) -> 3863.51 | J57: =SUM(J58:J61) -> 14795.36 | AH57: =IF(E57=0,0,(E57/AD57)-1) -> 0 | AI57: =IF(F57=0,0,(F57/AE57)-1) -> 0 | AJ57: =IF(G57=0,0,(G57/AF57)-1) -> 0
...

Sheet Prefixos
A1: Relação das Dependências do Lote 03 - São José dos Campos (SP)
A4: PREFIXO | B4: SB | C4: NOME DA AGÊNCIA | D4: ENDEREÇO | E4: MUNICÍPIO
A5: 76 | B5: 0 | C5: TAUBATE | D5: PCA.DOM EPAMINONDAS 84 | E5: TAUBATE
A6: 76 | B6: 4 | C6: MEX-1.B AV EX | D6: ESTR.DOS REMEDIOS 2135 | E6: TAUBATE
A7: 175 | B7: 0 | C7: SAO JOSE DOS CAMPOS | D7: AVENIDA DOUTOR NELSON D'AVILA _149 | E7: SAO JOSE DOS CAMPOS
A8: 294 | B8: 0 | C8: MOGI DAS CRUZES | D8: AV.VOL.FERNANDO PINHEIRO FRANCO 432 | E8: MOGI DAS CRUZES
A9: 306 | B9: 0 | C9: GUARATINGUETA | D9: RUA MONSENHOR FILIPPO 193 | E9: GUARATINGUETA
A10: 306 | B10: 1 | C10: FAB-E E A R | D10: AV.BRIG.ADHEMAR LIRIO S/N | E10: GUARATINGUETA
A11: 449 | B11: 0 | C11: CRUZEIRO-SP | D11: R.CAP.NECO 320/326 | E11: CRUZEIRO
A12: 574 | B12: 0 | C12: PINDAMONHANGABA | D12: PCA.MONS.MARCONDES 90 | E12: PINDAMONHANGABA
A13: 683 | B13: 0 | C13: JACAREI | D13: AV SEN JOAQUIM M M DE SIQUEIRA 25 | E13: JACAREI
A14: 715 | B14: 0 | C14: SAO SEBASTIAO-SP | D14: R.DUQUE DE CAXIAS 204 | E14: SAO SEBASTIAO
A15: 718 | B15: 0 | C15: SUZANO | D15: RUA GENERAL FRANCISCO GLICERIO 472 | E15: SUZANO
A16: 857 | B16: 0 | C16: LORENA | D16: PCA.DR.ARNOLFO DE AZEVEDO 93 | E16: LORENA
... A112: 175 | B112: 26 | C112: PETROBRAS-REF.H.LAG | D112: ROD.PRES.DUTRA KM 143 S/N | E112: SAO JOSE DOS CAMPOS

Sheet BDI
B1: O interessado deverá preencher os campos em amarelo de forma a obter o valor do BDI. | E1: O BDI pode ser alterado pela interessada. A alteração do BDI afeta o valor final da proposta. O valor do BDI deverá ser igual ao da proposta a ser apresentada.
B3: COMPOSIÇÃO ESTIMADA DO BDI (DESONERADO)
B6: ÍNDICES BDI - Serviços, subcontratações e acionamentos de Serviços de Engenharia.
B9: CUSTOS INDIRETOS
B10: Administração Central (AC) | C10: 0.03
B11: Seguros (S) + Garantia (G) | C11: 0.008
B12: Riscos R) | C12: 0.0097
B13: Despesas Financeiras (DF) | C13: 0.0059
B14: BONIFICAÇÃO
B15: Lucro Bruto (LB) | C15: 0.0616
B16: TRIBUTOS (T)
B17: ISS | C17: 0.05
B18: PIS / PASEP | C18: 0.0065
B19: COFINS | C19: 0.03
B20: CPRB | C20: 0.045
B21: BDI SERVIÇOS | C21: =ROUND(((1+(C10+C11+C12))*(1+C13)*(1+C15))/(1-(C17+C18+C19+C20))-1,4) -> 0.2882
B22: BDI = [[(1+(AC+S+G+R))*(1+DF)*(1+LB)]/(1-T)]-1
B26: 1 - O cálculo do BDI segue a metodologia estabelecida no item 9.10 do Voto do Acórdão 2369/2011 - TCU - Plenário. O IR e a CSLL não fazem parte do cálculo. 2 - Valores Referenciais dados pelo Acórdão 2622/2013 - TCU - Plenário. 3 - A parcela referente aos Seguros (S) é inversa à parcela de Riscos (R), ou seja, quanto maior a cobertura dos seguros contratados, menor a taxa de risco a ser considerada no BDI. Sendo assim, optou-se por representá-las na planilha de forma unificada. Poderão estar contabilizados na parcela os Seguros de Risco de Engenharia e de Responsabilidade Civil, dentre outros. 4 - Conforme orientações do TCU, publicadas no guia ORIENTAÇÕES PARA ELABORAÇÃO DE PLANILHAS ORÇAMENTÁRIAS DE OBRAS PÚBLICAS, a CPRB (Contribuição Previdenciária Sobre a Receita Bruta) deve ser incluída no cálculo do BDI de orçamentos que consideram a desoneração da folha de pagamentos.
B28: Observação: O PROPONENTE utilizará a incidência da CPRB somente se estiver enquadrado como desonerado.
